Workbook
Name AFG: Lookup_TEAMS!$B$5
Name AUS: Lookup_TEAMS!$B$6
Name BAN: Lookup_TEAMS!$B$7
Name BATROWS: Rawdata_Match!$P$2
Name BOWLROWS: Rawdata_Match!$BJ$3
Name ENG: Lookup_TEAMS!$B$8
Name FLAGS: Lookup_TEAMS!$B$5:$B$6
Name I_MATCHNO: #REF!
Name I_TEAM: #REF!
Name IND: Lookup_TEAMS!$B$9
Name IRE: Lookup_TEAMS!$B$10
Name MatchNameList: T_MATCHSUM[MATCH NAME]
Name Matchnumlist: T_MATCHSUM[Match Number]
Name NZ: Lookup_TEAMS!$B$11
Name PAK: Lookup_TEAMS!$B$12
Name SAF: Lookup_TEAMS!$B$14
Name SCO: Lookup_TEAMS!$B$13
Name SL: Lookup_TEAMS!$B$15
Name TEAMABR: Lookup_TEAMS!$C$5:$C$18
Name TeamFlag1: INDIRECT(#REF!)
Name TeamFlag2: INDIRECT(#REF!)
Name TEAMNMS: Lookup_TEAMS!$A$5:$A$18
Name TVIEWFLAG: INDIRECT(#REF!)
Name UAE: Lookup_TEAMS!$B$16
Name WI: Lookup_TEAMS!$B$17
Name ZIM: Lookup_TEAMS!$B$18

Sheet Rawdata_Match
P2: =ROWS(T_BATTINGDATA[Match]) -> 863
A3: BATTING | R3: EXTRAS | AA3: TOTAL SCORE | BJ3: =ROWS(Table9[Match Number]) -> 585
A5: Match | B5: Team | C5: Batsman | D5: Dismissal | E5: R | F5: M | G5: B | H5: 4s | I5: 6s | J5: SR | K5: Bat Number | L5: LINK | M5: SEL TEAM BAT | N5: SEL TEAM RUNS | O5: BATSMAN NAME | P5: Batsman Cum Score | R5: Match Number | S5: Team Batting | T5: LB | U5: W | V5: NB | W5: BYES | X5: TOTAL | Y5: LINK | AA5: Match Number | AB5: Team | AC5: Wickets | AD5: Total | AE5: RPO | AF5: Overs | AG5: LINK | AH5: ORDER | AI5: ORDER LINK | AJ5: BOWLING TEAM | AK5: Counting Overs | AL5: Counting balls | AM5: Counting Actual Balls | AN5: Counted Runs | AP5: Match Number | AQ5: Team | AR5: Bowler | AS5: Overs | AT5: Maidens | AU5: Runs | AV5: Wickets | AW5: Econ | AX5: 0s | AY5: 4s | AZ5: 6s | BA5: Wides | BB5: No balls | BC5: BOWL NUM | BD5: LINK | BE5: SEL TEAM BOWLER | BF5: BALLS BOWLED | BG5: BATTING TEAM | BH5: SEL TEAM WICKETS | BI5: VALUE WICKETS | BJ5: BOWLER CUML WICKETS | BK5: BOWLER CUML RUNS | BL5: BOWLER CUML VALUE
A6: 13 | B6: India | C6: RG Sharma | D6: run out (de Villiers) | E6: 0 | F6: 13 | G6: 6 | H6: 0 | I6: 0 | J6: 0 | K6: 1 | L6: =CONCATENATE(T_BATTINGDATA[[#This Row],[Match]],T_BATTINGDATA[[#This Row],[Team]],T_BATTINGDATA[[#This Row],[Bat Number]]) -> 13India1 | M6: =IFERROR(IF(AND(T_BATTINGDATA[[#This Row],[Team]]=I_TEAM,IFERROR(IF(MATCH(T_BATTINGDATA[[#This Row],[BATSMAN NAME]],$O$5:O5,0)>0,0),1)),1,0),"") | N6: =IF(T_BATTINGDATA[[#This Row],[Team]]=I_TEAM,T_BATTINGDATA[[#This Row],[R]],0) -> #REF! | O6: =LEFT(T_BATTINGDATA[[#This Row],[Batsman]],IFERROR(FIND("*",T_BATTINGDATA[[#This Row],[Batsman]])-1,IFERROR(FIND("†",T_BATTINGDATA[[#This Row],[Batsman]])-1,LEN(T_BATTINGDATA[[#This Row],[Batsman]])))) -> RG Sharma | P6: =IFERROR(IF(MATCH(T_BATTINGDATA[[#This Row],[BATSMAN NAME]],OFFSET(O7,0,0,BATROWS-ROW(O6)-ROW(T_BATTINGDATA[[#Headers],[BATSMAN NAME]])),0)>0,0,SUMIF($O$6:O6,T_BATTINGDATA[[#This Row],[BATSMAN NAME]],$E$6:E6)),SUMIF($O$6:O6,T_BATTINGDATA[[#This Row],[BATSMAN NAME]],$E$6:E6)) -> 0 | R6: 13 | S6: India | T6: 2 | U6: 6 | V6: 2 | X6: 10 | Y6: =CONCATENATE(T_EXTRAS[[#This Row],[Match Number]],T_EXTRAS[[#This Row],[Team Batting]]) -> 13India | AA6: 1 | AB6: New Zealand | AC6: 6 | AD6: 331 | AE6: 6.62 | AF6: 50 | AG6: =T_MTOTAL[[#This Row],[Match Number]]&T_MTOTAL[[#This Row],[Team]] -> 1New Zealand | AH6: 1 | AI6: =T_MTOTAL[[#This Row],[Match Number]]&" "&T_MTOTAL[[#This Row],[ORDER]] -> 1 1 | AJ6: =IF(INDEX(T_MATCHSUM[TEAM ONE],MATCH(T_MTOTAL[[#This Row],[Match Number]],T_MATCHSUM[Match Number],0))=T_MTOTAL[[#This Row],[Team]],INDEX(T_MATCHSUM[TEAM TWO],MATCH(T_MTOTAL[[#This Row],[Match Number]],T_MATCHSUM[Match Number],0)),INDEX(T_MATCHSUM[TEAM ONE],MATCH(T_MTOTAL[[#This Row],[Match Number]],T_MATCHSUM[Match Number],0))) -> SRI LANKA | AK6: =IF(OR(T_MTOTAL[[#This Row],[ORDER LINK]]="32 2",T_MTOTAL[[#This Row],[ORDER LINK]]="36 2"),50,IFERROR(IF(MATCH(T_MTOTAL[[#This Row],[ORDER LINK]],T_DL[link],0)>0, INDEX(T_DL[D/L Overs],MATCH(T_MTOTAL[[#This Row],[ORDER LINK]],T_DL[link],0)),IF(T_MTOTAL[[#This Row],[Wickets]]=10, 50,T_MTOTAL[[#This Row],[Overs]])),IF(T_MTOTAL[[#This Row],[Wickets]]=10, 50,T_MTOTAL[[#This Row],[Overs]]))) -> 50 | AL6: =(LEFT(T_MTOTAL[[#This Row],[Counting Overs]],IFERROR(FIND(".",T_MTOTAL[[#This Row],[Counting Overs]])-1,LEN(T_MTOTAL[[#This Row],[Counting Overs]])))*6) + IFERROR(IF(FIND(".",T_MTOTAL[[#This Row],[Counting Overs]])+1>0,RIGHT(T_MTOTAL[[#This Row],[Counting Overs]],1),0),0) -> 300 | AM6: =(LEFT(T_MTOTAL[[#This Row],[Overs]],IFERROR(FIND(".",T_MTOTAL[[#This Row],[Overs]])-1,LEN(T_MTOTAL[[#This Row],[Overs]])))*6) + IFERROR(IF(FIND(".",T_MTOTAL[[#This Row],[Overs]])+1>0,RIGHT(T_MTOTAL[[#This Row],[Overs]],1),0),0) -> 300 | AN6: =IFERROR(IF(MATCH(T_MTOTAL[[#This Row],[ORDER LINK]],T_DL[link],0)>0,INDEX(T_DL[d/l score],MATCH(T_MTOTAL[[#This Row],[ORDER LINK]],T_DL[link],0)),""),T_MTOTAL[[#This Row],[Total]]) -> 331 | AP6: 13 | AQ6: South Africa | AR6: DW Steyn | AS6: 10 | AT6: 1 | AU6: 55 | AV6: 1 | AW6: 5.5 | AX6: 36 | AY6: 6 | AZ6: 2 | BC6: 1 | BD6: =CONCATENATE(Table9[[#This Row],[Match Number]],Table9[[#This Row],[Team]],Table9[[#This Row],[BOWL NUM]]) -> 13South Africa1 | BE6: =IFERROR(IF(AND(Table9[[#This Row],[Team]]=I_TEAM,IFERROR(IF(MATCH(Table9[[#This Row],[Bowler]],$AR$5:AR5,0)>0,0),1)),1,0),"") | BF6: =(LEFT(Table9[[#This Row],[Overs]],IFERROR(FIND(".",Table9[[#This Row],[Overs]])-1,LEN(Table9[[#This Row],[Overs]])))*6) + IFERROR(IF(FIND(".",Table9[[#This Row],[Overs]])+1>0,RIGHT(Table9[[#This Row],[Overs]],1),0),0) -> 60 | BG6: =IF(INDEX(T_MATCHSUM[TEAM ONE],MATCH(Table9[[#This Row],[Match Number]],T_MATCHSUM[Match Number],0))=Table9[[#This Row],[Team]],INDEX(T_MATCHSUM[TEAM TWO],MATCH(Table9[[#This Row],[Match Number]],T_MATCHSUM[Match Number],0)),INDEX(T_MATCHSUM[TEAM ONE],MATCH(Table9[[#This Row],[Match Number]],T_MATCHSUM[Match Number],0))) -> INDIA | BH6: =IF(Table9[[#This Row],[Team]]=I_TEAM,Table9[[#This Row],[Wickets]]*100-Table9[[#This Row],[Runs]],0) -> #REF! | BI6: =Table9[[#This Row],[Wickets]]*100-Table9[[#This Row],[Runs]] -> 45 | BJ6: =IFERROR(IF(MATCH(Table9[[#This Row],[Bowler]],OFFSET(AR7,0,0,BOWLROWS-ROW(AR6)-ROW(Table9[[#Headers],[BOWLER CUML WICKETS]])),0)>0,0,SUMIF($AR$6:AR6,Table9[[#This Row],[Bowler]],$AV$6:AV6)),SUMIF($AR$6:AR6,Table9[[#This Row],[Bowler]],$AV$6:AV6)) -> 0 | BK6: =IFERROR(IF(MATCH(Table9[[#This Row],[Bowler]],OFFSET(AR7,0,0,BOWLROWS-ROW(AR6)-ROW(Table9[[#Headers],[BOWLER CUML WICKETS]])),0)>0,0,SUMIF($AR$6:AR6,Table9[[#This Row],[Bowler]],$AU$6:AU6)),SUMIF($AR$6:AR6,Table9[[#This Row],[Bowler]],$AU$6:AU6)) -> 0 | BL6: =Table9[[#This Row],[BOWLER CUML WICKETS]]*100-Table9[[#This Row],[BOWLER CUML RUNS]] -> 0
A7: 13 | B7: India | C7: S Dhawan | D7: c Amla b Parnell | E7: 137 | F7: 199 | G7: 146 | H7: 16 | I7: 2 | J7: 93.83 | K7: 2 | L7: =CONCATENATE(T_BATTINGDATA[[#This Row],[Match]],T_BATTINGDATA[[#This Row],[Team]],T_BATTINGDATA[[#This Row],[Bat Number]]) -> 13India2 | M7: =IFERROR(IF(AND(T_BATTINGDATA[[#This Row],[Team]]=I_TEAM,IFERROR(IF(MATCH(T_BATTINGDATA[[#This Row],[BATSMAN NAME]],$O$5:O6,0)>0,0),1)),1,0),"") | N7: =IF(T_BATTINGDATA[[#This Row],[Team]]=I_TEAM,T_BATTINGDATA[[#This Row],[R]],0) -> #REF! | O7: =LEFT(T_BATTINGDATA[[#This Row],[Batsman]],IFERROR(FIND("*",T_BATTINGDATA[[#This Row],[Batsman]])-1,IFERROR(FIND("†",T_BATTINGDATA[[#This Row],[Batsman]])-1,LEN(T_BATTINGDATA[[#This Row],[Batsman]])))) -> S Dhawan | P7: =IFERROR(IF(MATCH(T_BATTINGDATA[[#This Row],[BATSMAN NAME]],OFFSET(O8,0,0,BATROWS-ROW(O7)-ROW(T_BATTINGDATA[[#Headers],[BATSMAN NAME]])),0)>0,0,SUMIF($O$6:O7,T_BATTINGDATA[[#This Row],[BATSMAN NAME]],$E$6:E7)),SUMIF($O$6:O7,T_BATTINGDATA[[#This Row],[BATSMAN NAME]],$E$6:E7)) -> 0 | R7: 13 | S7: South Africa | T7: 1 | U7: 6 | X7: 7 | Y7: =CONCATENATE(T_EXTRAS[[#This Row],[Match Number]],T_EXTRAS[[#This Row],[Team Batting]]) -> 13South Africa | AA7: 1 | AB7: Sri Lanka | AC7: 10 | AD7: 233 | AE7: 5.04 | AF7: 46.1 | AG7: =T_MTOTAL[[#This Row],[Match Number]]&T_MTOTAL[[#This Row],[Team]] -> 1Sri Lanka | AH7: 2 | AI7: =T_MTOTAL[[#This Row],[Match Number]]&" "&T_MTOTAL[[#This Row],[ORDER]] -> 1 2 | AJ7: =IF(INDEX(T_MATCHSUM[TEAM ONE],MATCH(T_MTOTAL[[#This Row],[Match Number]],T_MATCHSUM[Match Number],0))=T_MTOTAL[[#This Row],[Team]],INDEX(T_MATCHSUM[TEAM TWO],MATCH(T_MTOTAL[[#This Row],[Match Number]],T_MATCHSUM[Match Number],0)),INDEX(T_MATCHSUM[TEAM ONE],MATCH(T_MTOTAL[[#This Row],[Match Number]],T_MATCHSUM[Match Number],0))) -> NEW ZEALAND | AK7: =IF(OR(T_MTOTAL[[#This Row],[ORDER LINK]]="32 2",T_MTOTAL[[#This Row],[ORDER LINK]]="36 2"),50,IFERROR(IF(MATCH(T_MTOTAL[[#This Row],[ORDER LINK]],T_DL[link],0)>0, INDEX(T_DL[D/L Overs],MATCH(T_MTOTAL[[#This Row],[ORDER LINK]],T_DL[link],0)),IF(T_MTOTAL[[#This Row],[Wickets]]=10, 50,T_MTOTAL[[#This Row],[Overs]])),IF(T_MTOTAL[[#This Row],[Wickets]]=10, 50,T_MTOTAL[[#This Row],[Overs]]))) -> 50 | AL7: =(LEFT(T_MTOTAL[[#This Row],[Counting Overs]],IFERROR(FIND(".",T_MTOTAL[[#This Row],[Counting Overs]])-1,LEN(T_MTOTAL[[#This Row],[Counting Overs]])))*6) + IFERROR(IF(FIND(".",T_MTOTAL[[#This Row],[Counting Overs]])+1>0,RIGHT(T_MTOTAL[[#This Row],[Counting Overs]],1),0),0) -> 300 | AM7: =(LEFT(T_MTOTAL[[#This Row],[Overs]],IFERROR(FIND(".",T_MTOTAL[[#This Row],[Overs]])-1,LEN(T_MTOTAL[[#This Row],[Overs]])))*6) + IFERROR(IF(FIND(".",T_MTOTAL[[#This Row],[Overs]])+1>0,RIGHT(T_MTOTAL[[#This Row],[Overs]],1),0),0) -> 277 | AN7: =IFERROR(IF(MATCH(T_MTOTAL[[#This Row],[ORDER LINK]],T_DL[link],0)>0,INDEX(T_DL[d/l score],MATCH(T_MTOTAL[[#This Row],[ORDER LINK]],T_DL[link],0)),""),T_MTOTAL[[#This Row],[Total]]) -> 233 | AP7: 13 | AQ7: South Africa | AR7: VD Philander | AS7: 4 | AT7: 1 | AU7: 19 | AV7: 0 | AW7: 4.75 | AX7: 15 | AY7: 3 | AZ7: 0 | BC7: 2 | BD7: =CONCATENATE(Table9[[#This Row],[Match Number]],Table9[[#This Row],[Team]],Table9[[#This Row],[BOWL NUM]]) -> 13South Africa2 | BE7: =IFERROR(IF(AND(Table9[[#This Row],[Team]]=I_TEAM,IFERROR(IF(MATCH(Table9[[#This Row],[Bowler]],$AR$5:AR6,0)>0,0),1)),1,0),"") | BF7: =(LEFT(Table9[[#This Row],[Overs]],IFERROR(FIND(".",Table9[[#This Row],[Overs]])-1,LEN(Table9[[#This Row],[Overs]])))*6) + IFERROR(IF(FIND(".",Table9[[#This Row],[Overs]])+1>0,RIGHT(Table9[[#This Row],[Overs]],1),0),0) -> 24 | BG7: =IF(INDEX(T_MATCHSUM[TEAM ONE],MATCH(Table9[[#This Row],[Match Number]],T_MATCHSUM[Match Number],0))=Table9[[#This Row],[Team]],INDEX(T_MATCHSUM[TEAM TWO],MATCH(Table9[[#This Row],[Match Number]],T_MATCHSUM[Match Number],0)),INDEX(T_MATCHSUM[TEAM ONE],MATCH(Table9[[#This Row],[Match Number]],T_MATCHSUM[Match Number],0))) -> INDIA | BH7: =IF(Table9[[#This Row],[Team]]=I_TEAM,Table9[[#This Row],[Wickets]]*100-Table9[[#This Row],[Runs]],0) -> #REF! | BI7: =Table9[[#This Row],[Wickets]]*100-Table9[[#This Row],[Runs]] -> -19 | BJ7: =IFERROR(IF(MATCH(Table9[[#This Row],[Bowler]],OFFSET(AR8,0,0,BOWLROWS-ROW(AR7)-ROW(Table9[[#Headers],[BOWLER CUML WICKETS]])),0)>0,0,SUMIF($AR$6:AR7,Table9[[#This Row],[Bowler]],$AV$6:AV7)),SUMIF($AR$6:AR7,Table9[[#This Row],[Bowler]],$AV$6:AV7)) -> 0 | BK7: =IFERROR(IF(MATCH(Table9[[#This Row],[Bowler]],OFFSET(AR8,0,0,BOWLROWS-ROW(AR7)-ROW(Table9[[#Headers],[BOWLER CUML WICKETS]])),0)>0,0,SUMIF($AR$6:AR7,Table9[[#This Row],[Bowler]],$AU$6:AU7)),SUMIF($AR$6:AR7,Table9[[#This Row],[Bowler]],$AU$6:AU7)) -> 0 | BL7: =Table9[[#This Row],[BOWLER CUML WICKETS]]*100-Table9[[#This Row],[BOWLER CUML RUNS]] -> 0
A8: 13 | B8: India | C8: V Kohli | D8: c du Plessis b Imran Tahir | E8: 46 | F8: 106 | G8: 60 | H8: 3 | I8: 0 | J8: 76.66 | K8: 3 | L8: =CONCATENATE(T_BATTINGDATA[[#This Row],[Match]],T_BATTINGDATA[[#This Row],[Team]],T_BATTINGDATA[[#This Row],[Bat Number]]) -> 13India3 | M8: =IFERROR(IF(AND(T_BATTINGDATA[[#This Row],[Team]]=I_TEAM,IFERROR(IF(MATCH(T_BATTINGDATA[[#This Row],[BATSMAN NAME]],$O$5:O7,0)>0,0),1)),1,0),"") | N8: =IF(T_BATTINGDATA[[#This Row],[Team]]=I_TEAM,T_BATTINGDATA[[#This Row],[R]],0) -> #REF! | O8: =LEFT(T_BATTINGDATA[[#This Row],[Batsman]],IFERROR(FIND("*",T_BATTINGDATA[[#This Row],[Batsman]])-1,IFERROR(FIND("†",T_BATTINGDATA[[#This Row],[Batsman]])-1,LEN(T_BATTINGDATA[[#This Row],[Batsman]])))) -> V Kohli | P8: =IFERROR(IF(MATCH(T_BATTINGDATA[[#This Row],[BATSMAN NAME]],OFFSET(O9,0,0,BATROWS-ROW(O8)-ROW(T_BATTINGDATA[[#Headers],[BATSMAN NAME]])),0)>0,0,SUMIF($O$6:O8,T_BATTINGDATA[[#This Row],[BATSMAN NAME]],$E$6:E8)),SUMIF($O$6:O8,T_BATTINGDATA[[#This Row],[BATSMAN NAME]],$E$6:E8)) -> 0 | R8: 4 | S8: India | T8: 2 | U8: 3 | V8: 1 | X8: 6 | Y8: =CONCATENATE(T_EXTRAS[[#This Row],[Match Number]],T_EXTRAS[[#This Row],[Team Batting]]) -> 4India | AA8: 2 | AB8: Australia | AC8: 9 | AD8: 342 | AE8: 6.84 | AF8: 50 | AG8: =T_MTOTAL[[#This Row],[Match Number]]&T_MTOTAL[[#This Row],[Team]] -> 2Australia | AH8: 1 | AI8: =T_MTOTAL[[#This Row],[Match Number]]&" "&T_MTOTAL[[#This Row],[ORDER]] -> 2 1 | AJ8: =IF(INDEX(T_MATCHSUM[TEAM ONE],MATCH(T_MTOTAL[[#This Row],[Match Number]],T_MATCHSUM[Match Number],0))=T_MTOTAL[[#This Row],[Team]],INDEX(T_MATCHSUM[TEAM TWO],MATCH(T_MTOTAL[[#This Row],[Match Number]],T_MATCHSUM[Match Number],0)),INDEX(T_MATCHSUM[TEAM ONE],MATCH(T_MTOTAL[[#This Row],[Match Number]],T_MATCHSUM[Match Number],0))) -> ENGLAND | AK8: =IF(OR(T_MTOTAL[[#This Row],[ORDER LINK]]="32 2",T_MTOTAL[[#This Row],[ORDER LINK]]="36 2"),50,IFERROR(IF(MATCH(T_MTOTAL[[#This Row],[ORDER LINK]],T_DL[link],0)>0, INDEX(T_DL[D/L Overs],MATCH(T_MTOTAL[[#This Row],[ORDER LINK]],T_DL[link],0)),IF(T_MTOTAL[[#This Row],[Wickets]]=10, 50,T_MTOTAL[[#This Row],[Overs]])),IF(T_MTOTAL[[#This Row],[Wickets]]=10, 50,T_MTOTAL[[#This Row],[Overs]]))) -> 50 | AL8: =(LEFT(T_MTOTAL[[#This Row],[Counting Overs]],IFERROR(FIND(".",T_MTOTAL[[#This Row],[Counting Overs]])-1,LEN(T_MTOTAL[[#This Row],[Counting Overs]])))*6) + IFERROR(IF(FIND(".",T_MTOTAL[[#This Row],[Counting Overs]])+1>0,RIGHT(T_MTOTAL[[#This Row],[Counting Overs]],1),0),0) -> 300 | AM8: =(LEFT(T_MTOTAL[[#This Row],[Overs]],IFERROR(FIND(".",T_MTOTAL[[#This Row],[Overs]])-1,LEN(T_MTOTAL[[#This Row],[Overs]])))*6) + IFERROR(IF(FIND(".",T_MTOTAL[[#This Row],[Overs]])+1>0,RIGHT(T_MTOTAL[[#This Row],[Overs]],1),0),0) -> 300 | AN8: =IFERROR(IF(MATCH(T_MTOTAL[[#This Row],[ORDER LINK]],T_DL[link],0)>0,INDEX(T_DL[d/l score],MATCH(T_MTOTAL[[#This Row],[ORDER LINK]],T_DL[link],0)),""),T_MTOTAL[[#This Row],[Total]]) -> 342 | AP8: 13 | AQ8: South Africa | AR8: JP Duminy | AS8: 7 | AT8: 0 | AU8: 39 | AV8: 0 | AW8: 5.57 | AX8: 17 | AY8: 3 | AZ8: 0 | BA8: 1 | BC8: 3 | BD8: =CONCATENATE(Table9[[#This Row],[Match Number]],Table9[[#This Row],[Team]],Table9[[#This Row],[BOWL NUM]]) -> 13South Africa3 | BE8: =IFERROR(IF(AND(Table9[[#This Row],[Team]]=I_TEAM,IFERROR(IF(MATCH(Table9[[#This Row],[Bowler]],$AR$5:AR7,0)>0,0),1)),1,0),"") | BF8: =(LEFT(Table9[[#This Row],[Overs]],IFERROR(FIND(".",Table9[[#This Row],[Overs]])-1,LEN(Table9[[#This Row],[Overs]])))*6) + IFERROR(IF(FIND(".",Table9[[#This Row],[Overs]])+1>0,RIGHT(Table9[[#This Row],[Overs]],1),0),0) -> 42 | BG8: =IF(INDEX(T_MATCHSUM[TEAM ONE],MATCH(Table9[[#This Row],[Match Number]],T_MATCHSUM[Match Number],0))=Table9[[#This Row],[Team]],INDEX(T_MATCHSUM[TEAM TWO],MATCH(Table9[[#This Row],[Match Number]],T_MATCHSUM[Match Number],0)),INDEX(T_MATCHSUM[TEAM ONE],MATCH(Table9[[#This Row],[Match Number]],T_MATCHSUM[Match Number],0))) -> INDIA | BH8: =IF(Table9[[#This Row],[Team]]=I_TEAM,Table9[[#This Row],[Wickets]]*100-Table9[[#This Row],[Runs]],0) -> #REF! | BI8: =Table9[[#This Row],[Wickets]]*100-Table9[[#This Row],[Runs]] -> -39 | BJ8: =IFERROR(IF(MATCH(Table9[[#This Row],[Bowler]],OFFSET(AR9,0,0,BOWLROWS-ROW(AR8)-ROW(Table9[[#Headers],[BOWLER CUML WICKETS]])),0)>0,0,SUMIF($AR$6:AR8,Table9[[#This Row],[Bowler]],$AV$6:AV8)),SUMIF($AR$6:AR8,Table9[[#This Row],[Bowler]],$AV$6:AV8)) -> 0 | BK8: =IFERROR(IF(MATCH(Table9[[#This Row],[Bowler]],OFFSET(AR9,0,0,BOWLROWS-ROW(AR8)-ROW(Table9[[#Headers],[BOWLER CUML WICKETS]])),0)>0,0,SUMIF($AR$6:AR8,Table9[[#This Row],[Bowler]],$AU$6:AU8)),SUMIF($AR$6:AR8,Table9[[#This Row],[Bowler]],$AU$6:AU8)) -> 0 | BL8: =Table9[[#This Row],[BOWLER CUML WICKETS]]*100-Table9[[#This Row],[BOWLER CUML RUNS]] -> 0
A9: 13 | B9: India | C9: AM Rahane | D9: lbw b Steyn | E9: 79 | F9: 90 | G9: 60 | H9: 7 | I9: 3 | J9: 131.66 | K9: 4 | L9: =CONCATENATE(T_BATTINGDATA[[#This Row],[Match]],T_BATTINGDATA[[#This Row],[Team]],T_BATTINGDATA[[#This Row],[Bat Number]]) -> 13India4 | M9: =IFERROR(IF(AND(T_BATTINGDATA[[#This Row],[Team]]=I_TEAM,IFERROR(IF(MATCH(T_BATTINGDATA[[#This Row],[BATSMAN NAME]],$O$5:O8,0)>0,0),1)),1,0),"") | N9: =IF(T_BATTINGDATA[[#This Row],[Team]]=I_TEAM,T_BATTINGDATA[[#This Row],[R]],0) -> #REF! | O9: =LEFT(T_BATTINGDATA[[#This Row],[Batsman]],IFERROR(FIND("*",T_BATTINGDATA[[#This Row],[Batsman]])-1,IFERROR(FIND("†",T_BATTINGDATA[[#This Row],[Batsman]])-1,LEN(T_BATTINGDATA[[#This Row],[Batsman]])))) -> AM Rahane | P9: =IFERROR(IF(MATCH(T_BATTINGDATA[[#This Row],[BATSMAN NAME]],OFFSET(O10,0,0,BATROWS-ROW(O9)-ROW(T_BATTINGDATA[[#Headers],[BATSMAN NAME]])),0)>0,0,SUMIF($O$6:O9,T_BATTINGDATA[[#This Row],[BATSMAN NAME]],$E$6:E9)),SUMIF($O$6:O9,T_BATTINGDATA[[#This Row],[BATSMAN NAME]],$E$6:E9)) -> 0 | R9: 4 | S9: Pakistan | T9: 1 | U9: 10 | V9: 1 | X9: 12 | Y9: =CONCATENATE(T_EXTRAS[[#This Row],[Match Number]],T_EXTRAS[[#This Row],[Team Batting]]) -> 4Pakistan | AA9: 2 | AB9: England | AC9: 10 | AD9: 231 | AE9: 5.52 | AF9: 41.5 | AG9: =T_MTOTAL[[#This Row],[Match Number]]&T_MTOTAL[[#This Row],[Team]] -> 2England | AH9: 2 | AI9: =T_MTOTAL[[#This Row],[Match Number]]&" "&T_MTOTAL[[#This Row],[ORDER]] -> 2 2 | AJ9: =IF(INDEX(T_MATCHSUM[TEAM ONE],MATCH(T_MTOTAL[[#This Row],[Match Number]],T_MATCHSUM[Match Number],0))=T_MTOTAL[[#This Row],[Team]],INDEX(T_MATCHSUM[TEAM TWO],MATCH(T_MTOTAL[[#This Row],[Match Number]],T_MATCHSUM[Match Number],0)),INDEX(T_MATCHSUM[TEAM ONE],MATCH(T_MTOTAL[[#This Row],[Match Number]],T_MATCHSUM[Match Number],0))) -> AUSTRALIA | AK9: =IF(OR(T_MTOTAL[[#This Row],[ORDER LINK]]="32 2",T_MTOTAL[[#This Row],[ORDER LINK]]="36 2"),50,IFERROR(IF(MATCH(T_MTOTAL[[#This Row],[ORDER LINK]],T_DL[link],0)>0, INDEX(T_DL[D/L Overs],MATCH(T_MTOTAL[[#This Row],[ORDER LINK]],T_DL[link],0)),IF(T_MTOTAL[[#This Row],[Wickets]]=10, 50,T_MTOTAL[[#This Row],[Overs]])),IF(T_MTOTAL[[#This Row],[Wickets]]=10, 50,T_MTOTAL[[#This Row],[Overs]]))) -> 50 | AL9: =(LEFT(T_MTOTAL[[#This Row],[Counting Overs]],IFERROR(FIND(".",T_MTOTAL[[#This Row],[Counting Overs]])-1,LEN(T_MTOTAL[[#This Row],[Counting Overs]])))*6) + IFERROR(IF(FIND(".",T_MTOTAL[[#This Row],[Counting Overs]])+1>0,RIGHT(T_MTOTAL[[#This Row],[Counting Overs]],1),0),0) -> 300 | AM9: =(LEFT(T_MTOTAL[[#This Row],[Overs]],IFERROR(FIND(".",T_MTOTAL[[#This Row],[Overs]])-1,LEN(T_MTOTAL[[#This Row],[Overs]])))*6) + IFERROR(IF(FIND(".",T_MTOTAL[[#This Row],[Overs]])+1>0,RIGHT(T_MTOTAL[[#This Row],[Overs]],1),0),0) -> 251 | AN9: =IFERROR(IF(MATCH(T_MTOTAL[[#This Row],[ORDER LINK]],T_DL[link],0)>0,INDEX(T_DL[d/l score],MATCH(T_MTOTAL[[#This Row],[ORDER LINK]],T_DL[link],0)),""),T_MTOTAL[[#This Row],[Total]]) -> 231 | AP9: 13 | AQ9: South Africa | AR9: M Morkel | AS9: 10 | AT9: 0 | AU9: 59 | AV9: 2 | AW9: 5.9 | AX9: 29 | AY9: 6 | AZ9: 1 | BC9: 4 | BD9: =CONCATENATE(Table9[[#This Row],[Match Number]],Table9[[#This Row],[Team]],Table9[[#This Row],[BOWL NUM]]) -> 13South Africa4 | BE9: =IFERROR(IF(AND(Table9[[#This Row],[Team]]=I_TEAM,IFERROR(IF(MATCH(Table9[[#This Row],[Bowler]],$AR$5:AR8,0)>0,0),1)),1,0),"") | BF9: =(LEFT(Table9[[#This Row],[Overs]],IFERROR(FIND(".",Table9[[#This Row],[Overs]])-1,LEN(Table9[[#This Row],[Overs]])))*6) + IFERROR(IF(FIND(".",Table9[[#This Row],[Overs]])+1>0,RIGHT(Table9[[#This Row],[Overs]],1),0),0) -> 60 | BG9: =IF(INDEX(T_MATCHSUM[TEAM ONE],MATCH(Table9[[#This Row],[Match Number]],T_MATCHSUM[Match Number],0))=Table9[[#This Row],[Team]],INDEX(T_MATCHSUM[TEAM TWO],MATCH(Table9[[#This Row],[Match Number]],T_MATCHSUM[Match Number],0)),INDEX(T_MATCHSUM[TEAM ONE],MATCH(Table9[[#This Row],[Match Number]],T_MATCHSUM[Match Number],0))) -> INDIA | BH9: =IF(Table9[[#This Row],[Team]]=I_TEAM,Table9[[#This Row],[Wickets]]*100-Table9[[#This Row],[Runs]],0) -> #REF! | BI9: =Table9[[#This Row],[Wickets]]*100-Table9[[#This Row],[Runs]] -> 141 | BJ9: =IFERROR(IF(MATCH(Table9[[#This Row],[Bowler]],OFFSET(AR10,0,0,BOWLROWS-ROW(AR9)-ROW(Table9[[#Headers],[BOWLER CUML WICKETS]])),0)>0,0,SUMIF($AR$6:AR9,Table9[[#This Row],[Bowler]],$AV$6:AV9)),SUMIF($AR$6:AR9,Table9[[#This Row],[Bowler]],$AV$6:AV9)) -> 0 | BK9: =IFERROR(IF(MATCH(Table9[[#This Row],[Bowler]],OFFSET(AR10,0,0,BOWLROWS-ROW(AR9)-ROW(Table9[[#Headers],[BOWLER CUML WICKETS]])),0)>0,0,SUMIF($AR$6:AR9,Table9[[#This Row],[Bowler]],$AU$6:AU9)),SUMIF($AR$6:AR9,Table9[[#This Row],[Bowler]],$AU$6:AU9)) -> 0 | BL9: =Table9[[#This Row],[BOWLER CUML WICKETS]]*100-Table9[[#This Row],[BOWLER CUML RUNS]] -> 0
A10: 13 | B10: India | C10: SK Raina | D10: c sub (RR Rossouw) b Morkel | E10: 6 | F10: 6 | G10: 5 | H10: 1 | I10: 0 | J10: 120 | K10: 5 | L10: =CONCATENATE(T_BATTINGDATA[[#This Row],[Match]],T_BATTINGDATA[[#This Row],[Team]],T_BATTINGDATA[[#This Row],[Bat Number]]) -> 13India5 | M10: =IFERROR(IF(AND(T_BATTINGDATA[[#This Row],[Team]]=I_TEAM,IFERROR(IF(MATCH(T_BATTINGDATA[[#This Row],[BATSMAN NAME]],$O$5:O9,0)>0,0),1)),1,0),"") | N10: =IF(T_BATTINGDATA[[#This Row],[Team]]=I_TEAM,T_BATTINGDATA[[#This Row],[R]],0) -> #REF! | O10: =LEFT(T_BATTINGDATA[[#This Row],[Batsman]],IFERROR(FIND("*",T_BATTINGDATA[[#This Row],[Batsman]])-1,IFERROR(FIND("†",T_BATTINGDATA[[#This Row],[Batsman]])-1,LEN(T_BATTINGDATA[[#This Row],[Batsman]])))) -> SK Raina | P10: =IFERROR(IF(MATCH(T_BATTINGDATA[[#This Row],[BATSMAN NAME]],OFFSET(O11,0,0,BATROWS-ROW(O10)-ROW(T_BATTINGDATA[[#Headers],[BATSMAN NAME]])),0)>0,0,SUMIF($O$6:O10,T_BATTINGDATA[[#This Row],[BATSMAN NAME]],$E$6:E10)),SUMIF($O$6:O10,T_BATTINGDATA[[#This Row],[BATSMAN NAME]],$E$6:E10)) -> 0 | R10: 39 | S10: Zimbabwe | T10: 2 | U10: 7 | X10: 9 | Y10: =CONCATENATE(T_EXTRAS[[#This Row],[Match Number]],T_EXTRAS[[#This Row],[Team Batting]]) -> 39Zimbabwe | AA10: 3 | AB10: South Africa | AC10: 4 | AD10: 339 | AE10: 6.78 | AF10: 50 | AG10: =T_MTOTAL[[#This Row],[Match Number]]&T_MTOTAL[[#This Row],[Team]] -> 3South Africa | AH10: 1 | AI10: =T_MTOTAL[[#This Row],[Match Number]]&" "&T_MTOTAL[[#This Row],[ORDER]] -> 3 1 | AJ10: =IF(INDEX(T_MATCHSUM[TEAM ONE],MATCH(T_MTOTAL[[#This Row],[Match Number]],T_MATCHSUM[Match Number],0))=T_MTOTAL[[#This Row],[Team]],INDEX(T_MATCHSUM[TEAM TWO],MATCH(T_MTOTAL[[#This Row],[Match Number]],T_MATCHSUM[Match Number],0)),INDEX(T_MATCHSUM[TEAM ONE],MATCH(T_MTOTAL[[#This Row],[Match Number]],T_MATCHSUM[Match Number],0))) -> ZIMBABWE | AK10: =IF(OR(T_MTOTAL[[#This Row],[ORDER LINK]]="32 2",T_MTOTAL[[#This Row],[ORDER LINK]]="36 2"),50,IFERROR(IF(MATCH(T_MTOTAL[[#This Row],[ORDER LINK]],T_DL[link],0)>0, INDEX(T_DL[D/L Overs],MATCH(T_MTOTAL[[#This Row],[ORDER LINK]],T_DL[link],0)),IF(T_MTOTAL[[#This Row],[Wickets]]=10, 50,T_MTOTAL[[#This Row],[Overs]])),IF(T_MTOTAL[[#This Row],[Wickets]]=10, 50,T_MTOTAL[[#This Row],[Overs]]))) -> 50 | AL10: =(LEFT(T_MTOTAL[[#This Row],[Counting Overs]],IFERROR(FIND(".",T_MTOTAL[[#This Row],[Counting Overs]])-1,LEN(T_MTOTAL[[#This Row],[Counting Overs]])))*6) + IFERROR(IF(FIND(".",T_MTOTAL[[#This Row],[Counting Overs]])+1>0,RIGHT(T_MTOTAL[[#This Row],[Counting Overs]],1),0),0) -> 300 | AM10: =(LEFT(T_MTOTAL[[#This Row],[Overs]],IFERROR(FIND(".",T_MTOTAL[[#This Row],[Overs]])-1,LEN(T_MTOTAL[[#This Row],[Overs]])))*6) + IFERROR(IF(FIND(".",T_MTOTAL[[#This Row],[Overs]])+1>0,RIGHT(T_MTOTAL[[#This Row],[Overs]],1),0),0) -> 300 | AN10: =IFERROR(IF(MATCH(T_MTOTAL[[#This Row],[ORDER LINK]],T_DL[link],0)>0,INDEX(T_DL[d/l score],MATCH(T_MTOTAL[[#This Row],[ORDER LINK]],T_DL[link],0)),""),T_MTOTAL[[#This Row],[Total]]) -> 339 | AP10: 13 | AQ10: South Africa | AR10: Imran Tahir | AS10: 10 | AT10: 0 | AU10: 48 | AV10: 1 | AW10: 4.8 | AX10: 26 | AY10: 2 | AZ10: 1 | BA10: 1 | BC10: 5 | BD10: =CONCATENATE(Table9[[#This Row],[Match Number]],Table9[[#This Row],[Team]],Table9[[#This Row],[BOWL NUM]]) -> 13South Africa5 | BE10: =IFERROR(IF(AND(Table9[[#This Row],[Team]]=I_TEAM,IFERROR(IF(MATCH(Table9[[#This Row],[Bowler]],$AR$5:AR9,0)>0,0),1)),1,0),"") | BF10: =(LEFT(Table9[[#This Row],[Overs]],IFERROR(FIND(".",Table9[[#This Row],[Overs]])-1,LEN(Table9[[#This Row],[Overs]])))*6) + IFERROR(IF(FIND(".",Table9[[#This Row],[Overs]])+1>0,RIGHT(Table9[[#This Row],[Overs]],1),0),0) -> 60 | BG10: =IF(INDEX(T_MATCHSUM[TEAM ONE],MATCH(Table9[[#This Row],[Match Number]],T_MATCHSUM[Match Number],0))=Table9[[#This Row],[Team]],INDEX(T_MATCHSUM[TEAM TWO],MATCH(Table9[[#This Row],[Match Number]],T_MATCHSUM[Match Number],0)),INDEX(T_MATCHSUM[TEAM ONE],MATCH(Table9[[#This Row],[Match Number]],T_MATCHSUM[Match Number],0))) -> INDIA | BH10: =IF(Table9[[#This Row],[Team]]=I_TEAM,Table9[[#This Row],[Wickets]]*100-Table9[[#This Row],[Runs]],0) -> #REF! | BI10: =Table9[[#This Row],[Wickets]]*100-Table9[[#This Row],[Runs]] -> 52 | BJ10: =IFERROR(IF(MATCH(Table9[[#This Row],[Bowler]],OFFSET(AR11,0,0,BOWLROWS-ROW(AR10)-ROW(Table9[[#Headers],[BOWLER CUML WICKETS]])),0)>0,0,SUMIF($AR$6:AR10,Table9[[#This Row],[Bowler]],$AV$6:AV10)),SUMIF($AR$6:AR10,Table9[[#This Row],[Bowler]],$AV$6:AV10)) -> 0 | BK10: =IFERROR(IF(MATCH(Table9[[#This Row],[Bowler]],OFFSET(AR11,0,0,BOWLROWS-ROW(AR10)-ROW(Table9[[#Headers],[BOWLER CUML WICKETS]])),0)>0,0,SUMIF($AR$6:AR10,Table9[[#This Row],[Bowler]],$AU$6:AU10)),SUMIF($AR$6:AR10,Table9[[#This Row],[Bowler]],$AU$6:AU10)) -> 0 | BL10: =Table9[[#This Row],[BOWLER CUML WICKETS]]*100-Table9[[#This Row],[BOWLER CUML RUNS]] -> 0
A11: 13 | B11: India | C11: MS Dhoni*† | D11: c †de Kock b Morkel | E11: 18 | F11: 22 | G11: 11 | H11: 3 | I11: 0 | J11: 163.63 | K11: 6 | L11: =CONCATENATE(T_BATTINGDATA[[#This Row],[Match]],T_BATTINGDATA[[#This Row],[Team]],T_BATTINGDATA[[#This Row],[Bat Number]]) -> 13India6 | M11: =IFERROR(IF(AND(T_BATTINGDATA[[#This Row],[Team]]=I_TEAM,IFERROR(IF(MATCH(T_BATTINGDATA[[#This Row],[BATSMAN NAME]],$O$5:O10,0)>0,0),1)),1,0),"") | N11: =IF(T_BATTINGDATA[[#This Row],[Team]]=I_TEAM,T_BATTINGDATA[[#This Row],[R]],0) -> #REF! | O11: =LEFT(T_BATTINGDATA[[#This Row],[Batsman]],IFERROR(FIND("*",T_BATTINGDATA[[#This Row],[Batsman]])-1,IFERROR(FIND("†",T_BATTINGDATA[[#This Row],[Batsman]])-1,LEN(T_BATTINGDATA[[#This Row],[Batsman]])))) -> MS Dhoni | P11: =IFERROR(IF(MATCH(T_BATTINGDATA[[#This Row],[BATSMAN NAME]],OFFSET(O12,0,0,BATROWS-ROW(O11)-ROW(T_BATTINGDATA[[#Headers],[BATSMAN NAME]])),0)>0,0,SUMIF($O$6:O11,T_BATTINGDATA[[#This Row],[BATSMAN NAME]],$E$6:E11)),SUMIF($O$6:O11,T_BATTINGDATA[[#This Row],[BATSMAN NAME]],$E$6:E11)) -> 0 | R11: 39 | S11: India | T11: 2 | U11: 12 | V11: 1 | W11: 1 | X11: 16 | Y11: =CONCATENATE(T_EXTRAS[[#This Row],[Match Number]],T_EXTRAS[[#This Row],[Team Batting]]) -> 39India | AA11: 3 | AB11: Zimbabwe | AC11: 10 | AD11: 277 | AE11: 5.73 | AF11: 48.2 | AG11: =T_MTOTAL[[#This Row],[Match Number]]&T_MTOTAL[[#This Row],[Team]] -> 3Zimbabwe | AH11: 2 | AI11: =T_MTOTAL[[#This Row],[Match Number]]&" "&T_MTOTAL[[#This Row],[ORDER]] -> 3 2 | AJ11: =IF(INDEX(T_MATCHSUM[TEAM ONE],MATCH(T_MTOTAL[[#This Row],[Match Number]],T_MATCHSUM[Match Number],0))=T_MTOTAL[[#This Row],[Team]],INDEX(T_MATCHSUM[TEAM TWO],MATCH(T_MTOTAL[[#This Row],[Match Number]],T_MATCHSUM[Match Number],0)),INDEX(T_MATCHSUM[TEAM ONE],MATCH(T_MTOTAL[[#This Row],[Match Number]],T_MATCHSUM[Match Number],0))) -> SOUTH AFRICA | AK11: =IF(OR(T_MTOTAL[[#This Row],[ORDER LINK]]="32 2",T_MTOTAL[[#This Row],[ORDER LINK]]="36 2"),50,IFERROR(IF(MATCH(T_MTOTAL[[#This Row],[ORDER LINK]],T_DL[link],0)>0, INDEX(T_DL[D/L Overs],MATCH(T_MTOTAL[[#This Row],[ORDER LINK]],T_DL[link],0)),IF(T_MTOTAL[[#This Row],[Wickets]]=10, 50,T_MTOTAL[[#This Row],[Overs]])),IF(T_MTOTAL[[#This Row],[Wickets]]=10, 50,T_MTOTAL[[#This Row],[Overs]]))) -> 50 | AL11: =(LEFT(T_MTOTAL[[#This Row],[Counting Overs]],IFERROR(FIND(".",T_MTOTAL[[#This Row],[Counting Overs]])-1,LEN(T_MTOTAL[[#This Row],[Counting Overs]])))*6) + IFERROR(IF(FIND(".",T_MTOTAL[[#This Row],[Counting Overs]])+1>0,RIGHT(T_MTOTAL[[#This Row],[Counting Overs]],1),0),0) -> 300 | AM11: =(LEFT(T_MTOTAL[[#This Row],[Overs]],IFERROR(FIND(".",T_MTOTAL[[#This Row],[Overs]])-1,LEN(T_MTOTAL[[#This Row],[Overs]])))*6) + IFERROR(IF(FIND(".",T_MTOTAL[[#This Row],[Overs]])+1>0,RIGHT(T_MTOTAL[[#This Row],[Overs]],1),0),0) -> 290 | AN11: =IFERROR(IF(MATCH(T_MTOTAL[[#This Row],[ORDER LINK]],T_DL[link],0)>0,INDEX(T_DL[d/l score],MATCH(T_MTOTAL[[#This Row],[ORDER LINK]],T_DL[link],0)),""),T_MTOTAL[[#This Row],[Total]]) -> 277 | AP11: 13 | AQ11: South Africa | AR11: WD Parnell | AS11: 9 | AT11: 0 | AU11: 85 | AV11: 1 | AW11: 9.44 | AX11: 21 | AY11: 11 | AZ11: 1 | BA11: 4 | BB11: 2 | BC11: 6 | BD11: =CONCATENATE(Table9[[#This Row],[Match Number]],Table9[[#This Row],[Team]],Table9[[#This Row],[BOWL NUM]]) -> 13South Africa6 | BE11: =IFERROR(IF(AND(Table9[[#This Row],[Team]]=I_TEAM,IFERROR(IF(MATCH(Table9[[#This Row],[Bowler]],$AR$5:AR10,0)>0,0),1)),1,0),"") | BF11: =(LEFT(Table9[[#This Row],[Overs]],IFERROR(FIND(".",Table9[[#This Row],[Overs]])-1,LEN(Table9[[#This Row],[Overs]])))*6) + IFERROR(IF(FIND(".",Table9[[#This Row],[Overs]])+1>0,RIGHT(Table9[[#This Row],[Overs]],1),0),0) -> 54 | BG11: =IF(INDEX(T_MATCHSUM[TEAM ONE],MATCH(Table9[[#This Row],[Match Number]],T_MATCHSUM[Match Number],0))=Table9[[#This Row],[Team]],INDEX(T_MATCHSUM[TEAM TWO],MATCH(Table9[[#This Row],[Match Number]],T_MATCHSUM[Match Number],0)),INDEX(T_MATCHSUM[TEAM ONE],MATCH(Table9[[#This Row],[Match Number]],T_MATCHSUM[Match Number],0))) -> INDIA | BH11: =IF(Table9[[#This Row],[Team]]=I_TEAM,Table9[[#This Row],[Wickets]]*100-Table9[[#This Row],[Runs]],0) -> #REF! | BI11: =Table9[[#This Row],[Wickets]]*100-Table9[[#This Row],[Runs]] -> 15 | BJ11: =IFERROR(IF(MATCH(Table9[[#This Row],[Bowler]],OFFSET(AR12,0,0,BOWLROWS-ROW(AR11)-ROW(Table9[[#Headers],[BOWLER CUML WICKETS]])),0)>0,0,SUMIF($AR$6:AR11,Table9[[#This Row],[Bowler]],$AV$6:AV11)),SUMIF($AR$6:AR11,Table9[[#This Row],[Bowler]],$AV$6:AV11)) -> 1 | BK11: =IFERROR(IF(MATCH(Table9[[#This Row],[Bowler]],OFFSET(AR12,0,0,BOWLROWS-ROW(AR11)-ROW(Table9[[#Headers],[BOWLER CUML WICKETS]])),0)>0,0,SUMIF($AR$6:AR11,Table9[[#This Row],[Bowler]],$AU$6:AU11)),SUMIF($AR$6:AR11,Table9[[#This Row],[Bowler]],$AU$6:AU11)) -> 85 | BL11: =Table9[[#This Row],[BOWLER CUML WICKETS]]*100-Table9[[#This Row],[BOWLER CUML RUNS]] -> 15
A12: 13 | B12: India | C12: RA Jadeja | D12: run out (de Villiers) | E12: 2 | F12: 4 | G12: 4 | H12: 0 | I12: 0 | J12: 50 | K12: 7 | L12: =CONCATENATE(T_BATTINGDATA[[#This Row],[Match]],T_BATTINGDATA[[#This Row],[Team]],T_BATTINGDATA[[#This Row],[Bat Number]]) -> 13India7 | M12: =IFERROR(IF(AND(T_BATTINGDATA[[#This Row],[Team]]=I_TEAM,IFERROR(IF(MATCH(T_BATTINGDATA[[#This Row],[BATSMAN NAME]],$O$5:O11,0)>0,0),1)),1,0),"") | N12: =IF(T_BATTINGDATA[[#This Row],[Team]]=I_TEAM,T_BATTINGDATA[[#This Row],[R]],0) -> #REF! | O12: =LEFT(T_BATTINGDATA[[#This Row],[Batsman]],IFERROR(FIND("*",T_BATTINGDATA[[#This Row],[Batsman]])-1,IFERROR(FIND("†",T_BATTINGDATA[[#This Row],[Batsman]])-1,LEN(T_BATTINGDATA[[#This Row],[Batsman]])))) -> RA Jadeja | P12: =IFERROR(IF(MATCH(T_BATTINGDATA[[#This Row],[BATSMAN NAME]],OFFSET(O13,0,0,BATROWS-ROW(O12)-ROW(T_BATTINGDATA[[#Headers],[BATSMAN NAME]])),0)>0,0,SUMIF($O$6:O12,T_BATTINGDATA[[#This Row],[BATSMAN NAME]],$E$6:E12)),SUMIF($O$6:O12,T_BATTINGDATA[[#This Row],[BATSMAN NAME]],$E$6:E12)) -> 0 | R12: 21 | S12: UAE | T12: 4 | U12: 9 | X12: 13 | Y12: =CONCATENATE(T_EXTRAS[[#This Row],[Match Number]],T_EXTRAS[[#This Row],[Team Batting]]) -> 21UAE | AA12: 4 | AB12: India | AC12: 7 | AD12: 300 | AE12: 6 | AF12: 50 | AG12: =T_MTOTAL[[#This Row],[Match Number]]&T_MTOTAL[[#This Row],[Team]] -> 4India | AH12: 1 | AI12: =T_MTOTAL[[#This Row],[Match Number]]&" "&T_MTOTAL[[#This Row],[ORDER]] -> 4 1 | AJ12: =IF(INDEX(T_MATCHSUM[TEAM ONE],MATCH(T_MTOTAL[[#This Row],[Match Number]],T_MATCHSUM[Match Number],0))=T_MTOTAL[[#This Row],[Team]],INDEX(T_MATCHSUM[TEAM TWO],MATCH(T_MTOTAL[[#This Row],[Match Number]],T_MATCHSUM[Match Number],0)),INDEX(T_MATCHSUM[TEAM ONE],MATCH(T_MTOTAL[[#This Row],[Match Number]],T_MATCHSUM[Match Number],0))) -> PAKISTAN | AK12: =IF(OR(T_MTOTAL[[#This Row],[ORDER LINK]]="32 2",T_MTOTAL[[#This Row],[ORDER LINK]]="36 2"),50,IFERROR(IF(MATCH(T_MTOTAL[[#This Row],[ORDER LINK]],T_DL[link],0)>0, INDEX(T_DL[D/L Overs],MATCH(T_MTOTAL[[#This Row],[ORDER LINK]],T_DL[link],0)),IF(T_MTOTAL[[#This Row],[Wickets]]=10, 50,T_MTOTAL[[#This Row],[Overs]])),IF(T_MTOTAL[[#This Row],[Wickets]]=10, 50,T_MTOTAL[[#This Row],[Overs]]))) -> 50 | AL12: =(LEFT(T_MTOTAL[[#This Row],[Counting Overs]],IFERROR(FIND(".",T_MTOTAL[[#This Row],[Counting Overs]])-1,LEN(T_MTOTAL[[#This Row],[Counting Overs]])))*6) + IFERROR(IF(FIND(".",T_MTOTAL[[#This Row],[Counting Overs]])+1>0,RIGHT(T_MTOTAL[[#This Row],[Counting Overs]],1),0),0) -> 300 | AM12: =(LEFT(T_MTOTAL[[#This Row],[Overs]],IFERROR(FIND(".",T_MTOTAL[[#This Row],[Overs]])-1,LEN(T_MTOTAL[[#This Row],[Overs]])))*6) + IFERROR(IF(FIND(".",T_MTOTAL[[#This Row],[Overs]])+1>0,RIGHT(T_MTOTAL[[#This Row],[Overs]],1),0),0) -> 300 | AN12: =IFERROR(IF(MATCH(T_MTOTAL[[#This Row],[ORDER LINK]],T_DL[link],0)>0,INDEX(T_DL[d/l score],MATCH(T_MTOTAL[[#This Row],[ORDER LINK]],T_DL[link],0)),""),T_MTOTAL[[#This Row],[Total]]) -> 300 | AP12: 13 | AQ12: India | AR12: UT Yadav | AS12: 6 | AT12: 0 | AU12: 34 | AV12: 0 | AW12: 5.66 | AX12: 20 | AY12: 4 | AZ12: 0 | BA12: 1 | BC12: 1 | BD12: =CONCATENATE(Table9[[#This Row],[Match Number]],Table9[[#This Row],[Team]],Table9[[#This Row],[BOWL NUM]]) -> 13India1 | BE12: =IFERROR(IF(AND(Table9[[#This Row],[Team]]=I_TEAM,IFERROR(IF(MATCH(Table9[[#This Row],[Bowler]],$AR$5:AR11,0)>0,0),1)),1,0),"") | BF12: =(LEFT(Table9[[#This Row],[Overs]],IFERROR(FIND(".",Table9[[#This Row],[Overs]])-1,LEN(Table9[[#This Row],[Overs]])))*6) + IFERROR(IF(FIND(".",Table9[[#This Row],[Overs]])+1>0,RIGHT(Table9[[#This Row],[Overs]],1),0),0) -> 36 | BG12: =IF(INDEX(T_MATCHSUM[TEAM ONE],MATCH(Table9[[#This Row],[Match Number]],T_MATCHSUM[Match Number],0))=Table9[[#This Row],[Team]],INDEX(T_MATCHSUM[TEAM TWO],MATCH(Table9[[#This Row],[Match Number]],T_MATCHSUM[Match Number],0)),INDEX(T_MATCHSUM[TEAM ONE],MATCH(Table9[[#This Row],[Match Number]],T_MATCHSUM[Match Number],0))) -> SOUTH AFRICA | BH12: =IF(Table9[[#This Row],[Team]]=I_TEAM,Table9[[#This Row],[Wickets]]*100-Table9[[#This Row],[Runs]],0) -> #REF! | BI12: =Table9[[#This Row],[Wickets]]*100-Table9[[#This Row],[Runs]] -> -34 | BJ12: =IFERROR(IF(MATCH(Table9[[#This Row],[Bowler]],OFFSET(AR13,0,0,BOWLROWS-ROW(AR12)-ROW(Table9[[#Headers],[BOWLER CUML WICKETS]])),0)>0,0,SUMIF($AR$6:AR12,Table9[[#This Row],[Bowler]],$AV$6:AV12)),SUMIF($AR$6:AR12,Table9[[#This Row],[Bowler]],$AV$6:AV12)) -> 0 | BK12: =IFERROR(IF(MATCH(Table9[[#This Row],[Bowler]],OFFSET(AR13,0,0,BOWLROWS-ROW(AR12)-ROW(Table9[[#Headers],[BOWLER CUML WICKETS]])),0)>0,0,SUMIF($AR$6:AR12,Table9[[#This Row],[Bowler]],$AU$6:AU12)),SUMIF($AR$6:AR12,Table9[[#This Row],[Bowler]],$AU$6:AU12)) -> 0 | BL12: =Table9[[#This Row],[BOWLER CUML WICKETS]]*100-Table9[[#This Row],[BOWLER CUML RUNS]] -> 0
A13: 13 | B13: India | C13: R Ashwin | D13: not out | E13: 5 | F13: 14 | G13: 5 | H13: 0 | I13: 0 | J13: 100 | K13: 8 | L13: =CONCATENATE(T_BATTINGDATA[[#This Row],[Match]],T_BATTINGDATA[[#This Row],[Team]],T_BATTINGDATA[[#This Row],[Bat Number]]) -> 13India8 | M13: =IFERROR(IF(AND(T_BATTINGDATA[[#This Row],[Team]]=I_TEAM,IFERROR(IF(MATCH(T_BATTINGDATA[[#This Row],[BATSMAN NAME]],$O$5:O12,0)>0,0),1)),1,0),"") | N13: =IF(T_BATTINGDATA[[#This Row],[Team]]=I_TEAM,T_BATTINGDATA[[#This Row],[R]],0) -> #REF! | O13: =LEFT(T_BATTINGDATA[[#This Row],[Batsman]],IFERROR(FIND("*",T_BATTINGDATA[[#This Row],[Batsman]])-1,IFERROR(FIND("†",T_BATTINGDATA[[#This Row],[Batsman]])-1,LEN(T_BATTINGDATA[[#This Row],[Batsman]])))) -> R Ashwin | P13: =IFERROR(IF(MATCH(T_BATTINGDATA[[#This Row],[BATSMAN NAME]],OFFSET(O14,0,0,BATROWS-ROW(O13)-ROW(T_BATTINGDATA[[#Headers],[BATSMAN NAME]])),0)>0,0,SUMIF($O$6:O13,T_BATTINGDATA[[#This Row],[BATSMAN NAME]],$E$6:E13)),SUMIF($O$6:O13,T_BATTINGDATA[[#This Row],[BATSMAN NAME]],$E$6:E13)) -> 0 | R13: 21 | S13: India | T13: 0 | U13: 0 | V13: 0 | W13: 0 | X13: 0 | Y13: =CONCATENATE(T_EXTRAS[[#This Row],[Match Number]],T_EXTRAS[[#This Row],[Team Batting]]) -> 21India | AA13: 4 | AB13: Pakistan | AC13: 10 | AD13: 224 | AE13: 4.76 | AF13: 47 | AG13: =T_MTOTAL[[#This Row],[Match Number]]&T_MTOTAL[[#This Row],[Team]] -> 4Pakistan | AH13: 2 | AI13: =T_MTOTAL[[#This Row],[Match Number]]&" "&T_MTOTAL[[#This Row],[ORDER]] -> 4 2 | AJ13: =IF(INDEX(T_MATCHSUM[TEAM ONE],MATCH(T_MTOTAL[[#This Row],[Match Number]],T_MATCHSUM[Match Number],0))=T_MTOTAL[[#This Row],[Team]],INDEX(T_MATCHSUM[TEAM TWO],MATCH(T_MTOTAL[[#This Row],[Match Number]],T_MATCHSUM[Match Number],0)),INDEX(T_MATCHSUM[TEAM ONE],MATCH(T_MTOTAL[[#This Row],[Match Number]],T_MATCHSUM[Match Number],0))) -> INDIA | AK13: =IF(OR(T_MTOTAL[[#This Row],[ORDER LINK]]="32 2",T_MTOTAL[[#This Row],[ORDER LINK]]="36 2"),50,IFERROR(IF(MATCH(T_MTOTAL[[#This Row],[ORDER LINK]],T_DL[link],0)>0, INDEX(T_DL[D/L Overs],MATCH(T_MTOTAL[[#This Row],[ORDER LINK]],T_DL[link],0)),IF(T_MTOTAL[[#This Row],[Wickets]]=10, 50,T_MTOTAL[[#This Row],[Overs]])),IF(T_MTOTAL[[#This Row],[Wickets]]=10, 50,T_MTOTAL[[#This Row],[Overs]]))) -> 50 | AL13: =(LEFT(T_MTOTAL[[#This Row],[Counting Overs]],IFERROR(FIND(".",T_MTOTAL[[#This Row],[Counting Overs]])-1,LEN(T_MTOTAL[[#This Row],[Counting Overs]])))*6) + IFERROR(IF(FIND(".",T_MTOTAL[[#This Row],[Counting Overs]])+1>0,RIGHT(T_MTOTAL[[#This Row],[Counting Overs]],1),0),0) -> 300 | AM13: =(LEFT(T_MTOTAL[[#This Row],[Overs]],IFERROR(FIND(".",T_MTOTAL[[#This Row],[Overs]])-1,LEN(T_MTOTAL[[#This Row],[Overs]])))*6) + IFERROR(IF(FIND(".",T_MTOTAL[[#This Row],[Overs]])+1>0,RIGHT(T_MTOTAL[[#This Row],[Overs]],1),0),0) -> 282 | AN13: =IFERROR(IF(MATCH(T_MTOTAL[[#This Row],[ORDER LINK]],T_DL[link],0)>0,INDEX(T_DL[d/l score],MATCH(T_MTOTAL[[#This Row],[ORDER LINK]],T_DL[link],0)),""),T_MTOTAL[[#This Row],[Total]]) -> 224 | AP13: 13 | AQ13: India | AR13: Mohammed Shami | AS13: 8 | AT13: 1 | AU13: 30 | AV13: 2 | AW13: 3.75 | AX13: 30 | AY13: 2 | AZ13: 0 | BA13: 2 | BC13: 2 | BD13: =CONCATENATE(Table9[[#This Row],[Match Number]],Table9[[#This Row],[Team]],Table9[[#This Row],[BOWL NUM]]) -> 13India2 | BE13: =IFERROR(IF(AND(Table9[[#This Row],[Team]]=I_TEAM,IFERROR(IF(MATCH(Table9[[#This Row],[Bowler]],$AR$5:AR12,0)>0,0),1)),1,0),"") | BF13: =(LEFT(Table9[[#This Row],[Overs]],IFERROR(FIND(".",Table9[[#This Row],[Overs]])-1,LEN(Table9[[#This Row],[Overs]])))*6) + IFERROR(IF(FIND(".",Table9[[#This Row],[Overs]])+1>0,RIGHT(Table9[[#This Row],[Overs]],1),0),0) -> 48 | BG13: =IF(INDEX(T_MATCHSUM[TEAM ONE],MATCH(Table9[[#This Row],[Match Number]],T_MATCHSUM[Match Number],0))=Table9[[#This Row],[Team]],INDEX(T_MATCHSUM[TEAM TWO],MATCH(Table9[[#This Row],[Match Number]],T_MATCHSUM[Match Number],0)),INDEX(T_MATCHSUM[TEAM ONE],MATCH(Table9[[#This Row],[Match Number]],T_MATCHSUM[Match Number],0))) -> SOUTH AFRICA | BH13: =IF(Table9[[#This Row],[Team]]=I_TEAM,Table9[[#This Row],[Wickets]]*100-Table9[[#This Row],[Runs]],0) -> #REF! | BI13: =Table9[[#This Row],[Wickets]]*100-Table9[[#This Row],[Runs]] -> 170 | BJ13: =IFERROR(IF(MATCH(Table9[[#This Row],[Bowler]],OFFSET(AR14,0,0,BOWLROWS-ROW(AR13)-ROW(Table9[[#Headers],[BOWLER CUML WICKETS]])),0)>0,0,SUMIF($AR$6:AR13,Table9[[#This Row],[Bowler]],$AV$6:AV13)),SUMIF($AR$6:AR13,Table9[[#This Row],[Bowler]],$AV$6:AV13)) -> 0 | BK13: =IFERROR(IF(MATCH(Table9[[#This Row],[Bowler]],OFFSET(AR14,0,0,BOWLROWS-ROW(AR13)-ROW(Table9[[#Headers],[BOWLER CUML WICKETS]])),0)>0,0,SUMIF($AR$6:AR13,Table9[[#This Row],[Bowler]],$AU$6:AU13)),SUMIF($AR$6:AR13,Table9[[#This Row],[Bowler]],$AU$6:AU13)) -> 0 | BL13: =Table9[[#This Row],[BOWLER CUML WICKETS]]*100-Table9[[#This Row],[BOWLER CUML RUNS]] -> 0
A14: 13 | B14: India | C14: Mohammed Shami | D14: not out | E14: 4 | F14: 5 | G14: 5 | H14: 1 | I14: 0 | J14: 80 | K14: 9 | L14: =CONCATENATE(T_BATTINGDATA[[#This Row],[Match]],T_BATTINGDATA[[#This Row],[Team]],T_BATTINGDATA[[#This Row],[Bat Number]]) -> 13India9 | M14: =IFERROR(IF(AND(T_BATTINGDATA[[#This Row],[Team]]=I_TEAM,IFERROR(IF(MATCH(T_BATTINGDATA[[#This Row],[BATSMAN NAME]],$O$5:O13,0)>0,0),1)),1,0),"") | N14: =IF(T_BATTINGDATA[[#This Row],[Team]]=I_TEAM,T_BATTINGDATA[[#This Row],[R]],0) -> #REF! | O14: =LEFT(T_BATTINGDATA[[#This Row],[Batsman]],IFERROR(FIND("*",T_BATTINGDATA[[#This Row],[Batsman]])-1,IFERROR(FIND("†",T_BATTINGDATA[[#This Row],[Batsman]])-1,LEN(T_BATTINGDATA[[#This Row],[Batsman]])))) -> Mohammed Shami | P14: =IFERROR(IF(MATCH(T_BATTINGDATA[[#This Row],[BATSMAN NAME]],OFFSET(O15,0,0,BATROWS-ROW(O14)-ROW(T_BATTINGDATA[[#Headers],[BATSMAN NAME]])),0)>0,0,SUMIF($O$6:O14,T_BATTINGDATA[[#This Row],[BATSMAN NAME]],$E$6:E14)),SUMIF($O$6:O14,T_BATTINGDATA[[#This Row],[BATSMAN NAME]],$E$6:E14)) -> 0 | R14: 34 | S14: Ireland | T14: 2 | U14: 9 | X14: 11 | Y14: =CONCATENATE(T_EXTRAS[[#This Row],[Match Number]],T_EXTRAS[[#This Row],[Team Batting]]) -> 34Ireland | AA14: 5 | AB14: West Indies | AC14: 7 | AD14: 304 | AE14: 6.08 | AF14: 50 | AG14: =T_MTOTAL[[#This Row],[Match Number]]&T_MTOTAL[[#This Row],[Team]] -> 5West Indies | AH14: 1 | AI14: =T_MTOTAL[[#This Row],[Match Number]]&" "&T_MTOTAL[[#This Row],[ORDER]] -> 5 1 | AJ14: =IF(INDEX(T_MATCHSUM[TEAM ONE],MATCH(T_MTOTAL[[#This Row],[Match Number]],T_MATCHSUM[Match Number],0))=T_MTOTAL[[#This Row],[Team]],INDEX(T_MATCHSUM[TEAM TWO],MATCH(T_MTOTAL[[#This Row],[Match Number]],T_MATCHSUM[Match Number],0)),INDEX(T_MATCHSUM[TEAM ONE],MATCH(T_MTOTAL[[#This Row],[Match Number]],T_MATCHSUM[Match Number],0))) -> IRELAND | AK14: =IF(OR(T_MTOTAL[[#This Row],[ORDER LINK]]="32 2",T_MTOTAL[[#This Row],[ORDER LINK]]="36 2"),50,IFERROR(IF(MATCH(T_MTOTAL[[#This Row],[ORDER LINK]],T_DL[link],0)>0, INDEX(T_DL[D/L Overs],MATCH(T_MTOTAL[[#This Row],[ORDER LINK]],T_DL[link],0)),IF(T_MTOTAL[[#This Row],[Wickets]]=10, 50,T_MTOTAL[[#This Row],[Overs]])),IF(T_MTOTAL[[#This Row],[Wickets]]=10, 50,T_MTOTAL[[#This Row],[Overs]]))) -> 50 | AL14: =(LEFT(T_MTOTAL[[#This Row],[Counting Overs]],IFERROR(FIND(".",T_MTOTAL[[#This Row],[Counting Overs]])-1,LEN(T_MTOTAL[[#This Row],[Counting Overs]])))*6) + IFERROR(IF(FIND(".",T_MTOTAL[[#This Row],[Counting Overs]])+1>0,RIGHT(T_MTOTAL[[#This Row],[Counting Overs]],1),0),0) -> 300 | AM14: =(LEFT(T_MTOTAL[[#This Row],[Overs]],IFERROR(FIND(".",T_MTOTAL[[#This Row],[Overs]])-1,LEN(T_MTOTAL[[#This Row],[Overs]])))*6) + IFERROR(IF(FIND(".",T_MTOTAL[[#This Row],[Overs]])+1>0,RIGHT(T_MTOTAL[[#This Row],[Overs]],1),0),0) -> 300 | AN14: =IFERROR(IF(MATCH(T_MTOTAL[[#This Row],[ORDER LINK]],T_DL[link],0)>0,INDEX(T_DL[d/l score],MATCH(T_MTOTAL[[#This Row],[ORDER LINK]],T_DL[link],0)),""),T_MTOTAL[[#This Row],[Total]]) -> 304 | AP14: 13 | AQ14: India | AR14: MM Sharma | AS14: 7 | AT14: 0 | AU14: 31 | AV14: 2 | AW14: 4.42 | AX14: 25 | AY14: 3 | AZ14: 0 | BA14: 2 | BC14: 3 | BD14: =CONCATENATE(Table9[[#This Row],[Match Number]],Table9[[#This Row],[Team]],Table9[[#This Row],[BOWL NUM]]) -> 13India3 | BE14: =IFERROR(IF(AND(Table9[[#This Row],[Team]]=I_TEAM,IFERROR(IF(MATCH(Table9[[#This Row],[Bowler]],$AR$5:AR13,0)>0,0),1)),1,0),"") | BF14: =(LEFT(Table9[[#This Row],[Overs]],IFERROR(FIND(".",Table9[[#This Row],[Overs]])-1,LEN(Table9[[#This Row],[Overs]])))*6) + IFERROR(IF(FIND(".",Table9[[#This Row],[Overs]])+1>0,RIGHT(Table9[[#This Row],[Overs]],1),0),0) -> 42 | BG14: =IF(INDEX(T_MATCHSUM[TEAM ONE],MATCH(Table9[[#This Row],[Match Number]],T_MATCHSUM[Match Number],0))=Table9[[#This Row],[Team]],INDEX(T_MATCHSUM[TEAM TWO],MATCH(Table9[[#This Row],[Match Number]],T_MATCHSUM[Match Number],0)),INDEX(T_MATCHSUM[TEAM ONE],MATCH(Table9[[#This Row],[Match Number]],T_MATCHSUM[Match Number],0))) -> SOUTH AFRICA | BH14: =IF(Table9[[#This Row],[Team]]=I_TEAM,Table9[[#This Row],[Wickets]]*100-Table9[[#This Row],[Runs]],0) -> #REF! | BI14: =Table9[[#This Row],[Wickets]]*100-Table9[[#This Row],[Runs]] -> 169 | BJ14: =IFERROR(IF(MATCH(Table9[[#This Row],[Bowler]],OFFSET(AR15,0,0,BOWLROWS-ROW(AR14)-ROW(Table9[[#Headers],[BOWLER CUML WICKETS]])),0)>0,0,SUMIF($AR$6:AR14,Table9[[#This Row],[Bowler]],$AV$6:AV14)),SUMIF($AR$6:AR14,Table9[[#This Row],[Bowler]],$AV$6:AV14)) -> 0 | BK14: =IFERROR(IF(MATCH(Table9[[#This Row],[Bowler]],OFFSET(AR15,0,0,BOWLROWS-ROW(AR14)-ROW(Table9[[#Headers],[BOWLER CUML WICKETS]])),0)>0,0,SUMIF($AR$6:AR14,Table9[[#This Row],[Bowler]],$AU$6:AU14)),SUMIF($AR$6:AR14,Table9[[#This Row],[Bowler]],$AU$6:AU14)) -> 0 | BL14: =Table9[[#This Row],[BOWLER CUML WICKETS]]*100-Table9[[#This Row],[BOWLER CUML RUNS]] -> 0
A15: 13 | B15: South Africa | C15: HM Amla | D15: c Mohammed Shami b MM Sharma | E15: 22 | F15: 50 | G15: 28 | H15: 2 | I15: 0 | J15: 78.57 | K15: 1 | L15: =CONCATENATE(T_BATTINGDATA[[#This Row],[Match]],T_BATTINGDATA[[#This Row],[Team]],T_BATTINGDATA[[#This Row],[Bat Number]]) -> 13South Africa1 | M15: =IFERROR(IF(AND(T_BATTINGDATA[[#This Row],[Team]]=I_TEAM,IFERROR(IF(MATCH(T_BATTINGDATA[[#This Row],[BATSMAN NAME]],$O$5:O14,0)>0,0),1)),1,0),"") | N15: =IF(T_BATTINGDATA[[#This Row],[Team]]=I_TEAM,T_BATTINGDATA[[#This Row],[R]],0) -> #REF! | O15: =LEFT(T_BATTINGDATA[[#This Row],[Batsman]],IFERROR(FIND("*",T_BATTINGDATA[[#This Row],[Batsman]])-1,IFERROR(FIND("†",T_BATTINGDATA[[#This Row],[Batsman]])-1,LEN(T_BATTINGDATA[[#This Row],[Batsman]])))) -> HM Amla | P15: =IFERROR(IF(MATCH(T_BATTINGDATA[[#This Row],[BATSMAN NAME]],OFFSET(O16,0,0,BATROWS-ROW(O15)-ROW(T_BATTINGDATA[[#Headers],[BATSMAN NAME]])),0)>0,0,SUMIF($O$6:O15,T_BATTINGDATA[[#This Row],[BATSMAN NAME]],$E$6:E15)),SUMIF($O$6:O15,T_BATTINGDATA[[#This Row],[BATSMAN NAME]],$E$6:E15)) -> 0 | R15: 34 | S15: India | T15: 2 | U15: 13 | W15: 4 | X15: 19 | Y15: =CONCATENATE(T_EXTRAS[[#This Row],[Match Number]],T_EXTRAS[[#This Row],[Team Batting]]) -> 34India | AA15: 5 | AB15: Ireland | AC15: 6 | AD15: 307 | AE15: 6.69 | AF15: 45.5 | AG15: =T_MTOTAL[[#This Row],[Match Number]]&T_MTOTAL[[#This Row],[Team]] -> 5Ireland | AH15: 2 | AI15: =T_MTOTAL[[#This Row],[Match Number]]&" "&T_MTOTAL[[#This Row],[ORDER]] -> 5 2 | AJ15: =IF(INDEX(T_MATCHSUM[TEAM ONE],MATCH(T_MTOTAL[[#This Row],[Match Number]],T_MATCHSUM[Match Number],0))=T_MTOTAL[[#This Row],[Team]],INDEX(T_MATCHSUM[TEAM TWO],MATCH(T_MTOTAL[[#This Row],[Match Number]],T_MATCHSUM[Match Number],0)),INDEX(T_MATCHSUM[TEAM ONE],MATCH(T_MTOTAL[[#This Row],[Match Number]],T_MATCHSUM[Match Number],0))) -> WEST INDIES | AK15: =IF(OR(T_MTOTAL[[#This Row],[ORDER LINK]]="32 2",T_MTOTAL[[#This Row],[ORDER LINK]]="36 2"),50,IFERROR(IF(MATCH(T_MTOTAL[[#This Row],[ORDER LINK]],T_DL[link],0)>0, INDEX(T_DL[D/L Overs],MATCH(T_MTOTAL[[#This Row],[ORDER LINK]],T_DL[link],0)),IF(T_MTOTAL[[#This Row],[Wickets]]=10, 50,T_MTOTAL[[#This Row],[Overs]])),IF(T_MTOTAL[[#This Row],[Wickets]]=10, 50,T_MTOTAL[[#This Row],[Overs]]))) -> 45.5 | AL15: =(LEFT(T_MTOTAL[[#This Row],[Counting Overs]],IFERROR(FIND(".",T_MTOTAL[[#This Row],[Counting Overs]])-1,LEN(T_MTOTAL[[#This Row],[Counting Overs]])))*6) + IFERROR(IF(FIND(".",T_MTOTAL[[#This Row],[Counting Overs]])+1>0,RIGHT(T_MTOTAL[[#This Row],[Counting Overs]],1),0),0) -> 275 | AM15: =(LEFT(T_MTOTAL[[#This Row],[Overs]],IFERROR(FIND(".",T_MTOTAL[[#This Row],[Overs]])-1,LEN(T_MTOTAL[[#This Row],[Overs]])))*6) + IFERROR(IF(FIND(".",T_MTOTAL[[#This Row],[Overs]])+1>0,RIGHT(T_MTOTAL[[#This Row],[Overs]],1),0),0) -> 275 | AN15: =IFERROR(IF(MATCH(T_MTOTAL[[#This Row],[ORDER LINK]],T_DL[link],0)>0,INDEX(T_DL[d/l score],MATCH(T_MTOTAL[[#This Row],[ORDER LINK]],T_DL[link],0)),""),T_MTOTAL[[#This Row],[Total]]) -> 307 | AP15: 13 | AQ15: India | AR15: RA Jadeja | AS15: 8.2 | AT15: 0 | AU15: 37 | AV15: 1 | AW15: 4.44 | AX15: 22 | AY15: 2 | AZ15: 0 | BA15: 1 | BC15: 4 | BD15: =CONCATENATE(Table9[[#This Row],[Match Number]],Table9[[#This Row],[Team]],Table9[[#This Row],[BOWL NUM]]) -> 13India4 | BE15: =IFERROR(IF(AND(Table9[[#This Row],[Team]]=I_TEAM,IFERROR(IF(MATCH(Table9[[#This Row],[Bowler]],$AR$5:AR14,0)>0,0),1)),1,0),"") | BF15: =(LEFT(Table9[[#This Row],[Overs]],IFERROR(FIND(".",Table9[[#This Row],[Overs]])-1,LEN(Table9[[#This Row],[Overs]])))*6) + IFERROR(IF(FIND(".",Table9[[#This Row],[Overs]])+1>0,RIGHT(Table9[[#This Row],[Overs]],1),0),0) -> 50 | BG15: =IF(INDEX(T_MATCHSUM[TEAM ONE],MATCH(Table9[[#This Row],[Match Number]],T_MATCHSUM[Match Number],0))=Table9[[#This Row],[Team]],INDEX(T_MATCHSUM[TEAM TWO],MATCH(Table9[[#This Row],[Match Number]],T_MATCHSUM[Match Number],0)),INDEX(T_MATCHSUM[TEAM ONE],MATCH(Table9[[#This Row],[Match Number]],T_MATCHSUM[Match Number],0))) -> SOUTH AFRICA | BH15: =IF(Table9[[#This Row],[Team]]=I_TEAM,Table9[[#This Row],[Wickets]]*100-Table9[[#This Row],[Runs]],0) -> #REF! | BI15: =Table9[[#This Row],[Wickets]]*100-Table9[[#This Row],[Runs]] -> 63 | BJ15: =IFERROR(IF(MATCH(Table9[[#This Row],[Bowler]],OFFSET(AR16,0,0,BOWLROWS-ROW(AR15)-ROW(Table9[[#Headers],[BOWLER CUML WICKETS]])),0)>0,0,SUMIF($AR$6:AR15,Table9[[#This Row],[Bowler]],$AV$6:AV15)),SUMIF($AR$6:AR15,Table9[[#This Row],[Bowler]],$AV$6:AV15)) -> 0 | BK15: =IFERROR(IF(MATCH(Table9[[#This Row],[Bowler]],OFFSET(AR16,0,0,BOWLROWS-ROW(AR15)-ROW(Table9[[#Headers],[BOWLER CUML WICKETS]])),0)>0,0,SUMIF($AR$6:AR15,Table9[[#This Row],[Bowler]],$AU$6:AU15)),SUMIF($AR$6:AR15,Table9[[#This Row],[Bowler]],$AU$6:AU15)) -> 0 | BL15: =Table9[[#This Row],[BOWLER CUML WICKETS]]*100-Table9[[#This Row],[BOWLER CUML RUNS]] -> 0
A16: 13 | B16: South Africa | C16: Q de Kock† | D16: c Kohli b Mohammed Shami | E16: 7 | F16: 15 | G16: 15 | H16: 1 | I16: 0 | J16: 46.66 | K16: 2 | L16: =CONCATENATE(T_BATTINGDATA[[#This Row],[Match]],T_BATTINGDATA[[#This Row],[Team]],T_BATTINGDATA[[#This Row],[Bat Number]]) -> 13South Africa2 | M16: =IFERROR(IF(AND(T_BATTINGDATA[[#This Row],[Team]]=I_TEAM,IFERROR(IF(MATCH(T_BATTINGDATA[[#This Row],[BATSMAN NAME]],$O$5:O15,0)>0,0),1)),1,0),"") | N16: =IF(T_BATTINGDATA[[#This Row],[Team]]=I_TEAM,T_BATTINGDATA[[#This Row],[R]],0) -> #REF! | O16: =LEFT(T_BATTINGDATA[[#This Row],[Batsman]],IFERROR(FIND("*",T_BATTINGDATA[[#This Row],[Batsman]])-1,IFERROR(FIND("†",T_BATTINGDATA[[#This Row],[Batsman]])-1,LEN(T_BATTINGDATA[[#This Row],[Batsman]])))) -> Q de Kock | P16: =IFERROR(IF(MATCH(T_BATTINGDATA[[#This Row],[BATSMAN NAME]],OFFSET(O17,0,0,BATROWS-ROW(O16)-ROW(T_BATTINGDATA[[#Headers],[BATSMAN NAME]])),0)>0,0,SUMIF($O$6:O16,T_BATTINGDATA[[#This Row],[BATSMAN NAME]],$E$6:E16)),SUMIF($O$6:O16,T_BATTINGDATA[[#This Row],[BATSMAN NAME]],$E$6:E16)) -> 0 | R16: 28 | S16: West Indies | T16: 5 | U16: 16 | X16: 21 | Y16: =CONCATENATE(T_EXTRAS[[#This Row],[Match Number]],T_EXTRAS[[#This Row],[Team Batting]]) -> 28West Indies | AA16: 6 | AB16: Scotland | AC16: 10 | AD16: 142 | AE16: 3.9 | AF16: 36.2 | AG16: =T_MTOTAL[[#This Row],[Match Number]]&T_MTOTAL[[#This Row],[Team]] -> 6Scotland | AH16: 1 | AI16: =T_MTOTAL[[#This Row],[Match Number]]&" "&T_MTOTAL[[#This Row],[ORDER]] -> 6 1 | AJ16: =IF(INDEX(T_MATCHSUM[TEAM ONE],MATCH(T_MTOTAL[[#This Row],[Match Number]],T_MATCHSUM[Match Number],0))=T_MTOTAL[[#This Row],[Team]],INDEX(T_MATCHSUM[TEAM TWO],MATCH(T_MTOTAL[[#This Row],[Match Number]],T_MATCHSUM[Match Number],0)),INDEX(T_MATCHSUM[TEAM ONE],MATCH(T_MTOTAL[[#This Row],[Match Number]],T_MATCHSUM[Match Number],0))) -> NEW ZEALAND | AK16: =IF(OR(T_MTOTAL[[#This Row],[ORDER LINK]]="32 2",T_MTOTAL[[#This Row],[ORDER LINK]]="36 2"),50,IFERROR(IF(MATCH(T_MTOTAL[[#This Row],[ORDER LINK]],T_DL[link],0)>0, INDEX(T_DL[D/L Overs],MATCH(T_MTOTAL[[#This Row],[ORDER LINK]],T_DL[link],0)),IF(T_MTOTAL[[#This Row],[Wickets]]=10, 50,T_MTOTAL[[#This Row],[Overs]])),IF(T_MTOTAL[[#This Row],[Wickets]]=10, 50,T_MTOTAL[[#This Row],[Overs]]))) -> 50 | AL16: =(LEFT(T_MTOTAL[[#This Row],[Counting Overs]],IFERROR(FIND(".",T_MTOTAL[[#This Row],[Counting Overs]])-1,LEN(T_MTOTAL[[#This Row],[Counting Overs]])))*6) + IFERROR(IF(FIND(".",T_MTOTAL[[#This Row],[Counting Overs]])+1>0,RIGHT(T_MTOTAL[[#This Row],[Counting Overs]],1),0),0) -> 300 | AM16: =(LEFT(T_MTOTAL[[#This Row],[Overs]],IFERROR(FIND(".",T_MTOTAL[[#This Row],[Overs]])-1,LEN(T_MTOTAL[[#This Row],[Overs]])))*6) + IFERROR(IF(FIND(".",T_MTOTAL[[#This Row],[Overs]])+1>0,RIGHT(T_MTOTAL[[#This Row],[Overs]],1),0),0) -> 218 | AN16: =IFERROR(IF(MATCH(T_MTOTAL[[#This Row],[ORDER LINK]],T_DL[link],0)>0,INDEX(T_DL[d/l score],MATCH(T_MTOTAL[[#This Row],[ORDER LINK]],T_DL[link],0)),""),T_MTOTAL[[#This Row],[Total]]) -> 142 | AP16: 13 | AQ16: India | AR16: R Ashwin | AS16: 10 | AT16: 0 | AU16: 41 | AV16: 3 | AW16: 4.1 | AX16: 34 | AY16: 4 | AZ16: 0 | BC16: 5 | BD16: =CONCATENATE(Table9[[#This Row],[Match Number]],Table9[[#This Row],[Team]],Table9[[#This Row],[BOWL NUM]]) -> 13India5 | BE16: =IFERROR(IF(AND(Table9[[#This Row],[Team]]=I_TEAM,IFERROR(IF(MATCH(Table9[[#This Row],[Bowler]],$AR$5:AR15,0)>0,0),1)),1,0),"") | BF16: =(LEFT(Table9[[#This Row],[Overs]],IFERROR(FIND(".",Table9[[#This Row],[Overs]])-1,LEN(Table9[[#This Row],[Overs]])))*6) + IFERROR(IF(FIND(".",Table9[[#This Row],[Overs]])+1>0,RIGHT(Table9[[#This Row],[Overs]],1),0),0) -> 60 | BG16: =IF(INDEX(T_MATCHSUM[TEAM ONE],MATCH(Table9[[#This Row],[Match Number]],T_MATCHSUM[Match Number],0))=Table9[[#This Row],[Team]],INDEX(T_MATCHSUM[TEAM TWO],MATCH(Table9[[#This Row],[Match Number]],T_MATCHSUM[Match Number],0)),INDEX(T_MATCHSUM[TEAM ONE],MATCH(Table9[[#This Row],[Match Number]],T_MATCHSUM[Match Number],0))) -> SOUTH AFRICA | BH16: =IF(Table9[[#This Row],[Team]]=I_TEAM,Table9[[#This Row],[Wickets]]*100-Table9[[#This Row],[Runs]],0) -> #REF! | BI16: =Table9[[#This Row],[Wickets]]*100-Table9[[#This Row],[Runs]] -> 259 | BJ16: =IFERROR(IF(MATCH(Table9[[#This Row],[Bowler]],OFFSET(AR17,0,0,BOWLROWS-ROW(AR16)-ROW(Table9[[#Headers],[BOWLER CUML WICKETS]])),0)>0,0,SUMIF($AR$6:AR16,Table9[[#This Row],[Bowler]],$AV$6:AV16)),SUMIF($AR$6:AR16,Table9[[#This Row],[Bowler]],$AV$6:AV16)) -> 0 | BK16: =IFERROR(IF(MATCH(Table9[[#This Row],[Bowler]],OFFSET(AR17,0,0,BOWLROWS-ROW(AR16)-ROW(Table9[[#Headers],[BOWLER CUML WICKETS]])),0)>0,0,SUMIF($AR$6:AR16,Table9[[#This Row],[Bowler]],$AU$6:AU16)),SUMIF($AR$6:AR16,Table9[[#This Row],[Bowler]],$AU$6:AU16)) -> 0 | BL16: =Table9[[#This Row],[BOWLER CUML WICKETS]]*100-Table9[[#This Row],[BOWLER CUML RUNS]] -> 0
A17: 13 | B17: South Africa | C17: F du Plessis | D17: c Dhawan b MM Sharma | E17: 55 | F17: 98 | G17: 71 | H17: 5 | I17: 0 | J17: 77.46 | K17: 3 | L17: =CONCATENATE(T_BATTINGDATA[[#This Row],[Match]],T_BATTINGDATA[[#This Row],[Team]],T_BATTINGDATA[[#This Row],[Bat Number]]) -> 13South Africa3 | M17: =IFERROR(IF(AND(T_BATTINGDATA[[#This Row],[Team]]=I_TEAM,IFERROR(IF(MATCH(T_BATTINGDATA[[#This Row],[BATSMAN NAME]],$O$5:O16,0)>0,0),1)),1,0),"") | N17: =IF(T_BATTINGDATA[[#This Row],[Team]]=I_TEAM,T_BATTINGDATA[[#This Row],[R]],0) -> #REF! | O17: =LEFT(T_BATTINGDATA[[#This Row],[Batsman]],IFERROR(FIND("*",T_BATTINGDATA[[#This Row],[Batsman]])-1,IFERROR(FIND("†",T_BATTINGDATA[[#This Row],[Batsman]])-1,LEN(T_BATTINGDATA[[#This Row],[Batsman]])))) -> F du Plessis | P17: =IFERROR(IF(MATCH(T_BATTINGDATA[[#This Row],[BATSMAN NAME]],OFFSET(O18,0,0,BATROWS-ROW(O17)-ROW(T_BATTINGDATA[[#Headers],[BATSMAN NAME]])),0)>0,0,SUMIF($O$6:O17,T_BATTINGDATA[[#This Row],[BATSMAN NAME]],$E$6:E17)),SUMIF($O$6:O17,T_BATTINGDATA[[#This Row],[BATSMAN NAME]],$E$6:E17)) -> 0 | R17: 28 | S17: India | T17: 3 | U17: 19 | V17: 3 | W17: 1 | X17: 26 | Y17: =CONCATENATE(T_EXTRAS[[#This Row],[Match Number]],T_EXTRAS[[#This Row],[Team Batting]]) -> 28India | AA17: 6 | AB17: New Zealand | AC17: 7 | AD17: 146 | AE17: 5.87 | AF17: 24.5 | AG17: =T_MTOTAL[[#This Row],[Match Number]]&T_MTOTAL[[#This Row],[Team]] -> 6New Zealand | AH17: 2 | AI17: =T_MTOTAL[[#This Row],[Match Number]]&" "&T_MTOTAL[[#This Row],[ORDER]] -> 6 2 | AJ17: =IF(INDEX(T_MATCHSUM[TEAM ONE],MATCH(T_MTOTAL[[#This Row],[Match Number]],T_MATCHSUM[Match Number],0))=T_MTOTAL[[#This Row],[Team]],INDEX(T_MATCHSUM[TEAM TWO],MATCH(T_MTOTAL[[#This Row],[Match Number]],T_MATCHSUM[Match Number],0)),INDEX(T_MATCHSUM[TEAM ONE],MATCH(T_MTOTAL[[#This Row],[Match Number]],T_MATCHSUM[Match Number],0))) -> SCOTLAND | AK17: =IF(OR(T_MTOTAL[[#This Row],[ORDER LINK]]="32 2",T_MTOTAL[[#This Row],[ORDER LINK]]="36 2"),50,IFERROR(IF(MATCH(T_MTOTAL[[#This Row],[ORDER LINK]],T_DL[link],0)>0, INDEX(T_DL[D/L Overs],MATCH(T_MTOTAL[[#This Row],[ORDER LINK]],T_DL[link],0)),IF(T_MTOTAL[[#This Row],[Wickets]]=10, 50,T_MTOTAL[[#This Row],[Overs]])),IF(T_MTOTAL[[#This Row],[Wickets]]=10, 50,T_MTOTAL[[#This Row],[Overs]]))) -> 24.5 | AL17: =(LEFT(T_MTOTAL[[#This Row],[Counting Overs]],IFERROR(FIND(".",T_MTOTAL[[#This Row],[Counting Overs]])-1,LEN(T_MTOTAL[[#This Row],[Counting Overs]])))*6) + IFERROR(IF(FIND(".",T_MTOTAL[[#This Row],[Counting Overs]])+1>0,RIGHT(T_MTOTAL[[#This Row],[Counting Overs]],1),0),0) -> 149 | AM17: =(LEFT(T_MTOTAL[[#This Row],[Overs]],IFERROR(FIND(".",T_MTOTAL[[#This Row],[Overs]])-1,LEN(T_MTOTAL[[#This Row],[Overs]])))*6) + IFERROR(IF(FIND(".",T_MTOTAL[[#This Row],[Overs]])+1>0,RIGHT(T_MTOTAL[[#This Row],[Overs]],1),0),0) -> 149 | AN17: =IFERROR(IF(MATCH(T_MTOTAL[[#This Row],[ORDER LINK]],T_DL[link],0)>0,INDEX(T_DL[d/l score],MATCH(T_MTOTAL[[#This Row],[ORDER LINK]],T_DL[link],0)),""),T_MTOTAL[[#This Row],[Total]]) -> 146 | AP17: 13 | AQ17: India | AR17: SK Raina | AS17: 1 | AT17: 0 | AU17: 3 | AV17: 0 | AW17: 3 | AX17: 3 | AY17: 0 | AZ17: 0 | BC17: 6 | BD17: =CONCATENATE(Table9[[#This Row],[Match Number]],Table9[[#This Row],[Team]],Table9[[#This Row],[BOWL NUM]]) -> 13India6 | BE17: =IFERROR(IF(AND(Table9[[#This Row],[Team]]=I_TEAM,IFERROR(IF(MATCH(Table9[[#This Row],[Bowler]],$AR$5:AR16,0)>0,0),1)),1,0),"") | BF17: =(LEFT(Table9[[#This Row],[Overs]],IFERROR(FIND(".",Table9[[#This Row],[Overs]])-1,LEN(Table9[[#This Row],[Overs]])))*6) + IFERROR(IF(FIND(".",Table9[[#This Row],[Overs]])+1>0,RIGHT(Table9[[#This Row],[Overs]],1),0),0) -> 6 | BG17: =IF(INDEX(T_MATCHSUM[TEAM ONE],MATCH(Table9[[#This Row],[Match Number]],T_MATCHSUM[Match Number],0))=Table9[[#This Row],[Team]],INDEX(T_MATCHSUM[TEAM TWO],MATCH(Table9[[#This Row],[Match Number]],T_MATCHSUM[Match Number],0)),INDEX(T_MATCHSUM[TEAM ONE],MATCH(Table9[[#This Row],[Match Number]],T_MATCHSUM[Match Number],0))) -> SOUTH AFRICA | BH17: =IF(Table9[[#This Row],[Team]]=I_TEAM,Table9[[#This Row],[Wickets]]*100-Table9[[#This Row],[Runs]],0) -> #REF! | BI17: =Table9[[#This Row],[Wickets]]*100-Table9[[#This Row],[Runs]] -> -3 | BJ17: =IFERROR(IF(MATCH(Table9[[#This Row],[Bowler]],OFFSET(AR18,0,0,BOWLROWS-ROW(AR17)-ROW(Table9[[#Headers],[BOWLER CUML WICKETS]])),0)>0,0,SUMIF($AR$6:AR17,Table9[[#This Row],[Bowler]],$AV$6:AV17)),SUMIF($AR$6:AR17,Table9[[#This Row],[Bowler]],$AV$6:AV17)) -> 0 | BK17: =IFERROR(IF(MATCH(Table9[[#This Row],[Bowler]],OFFSET(AR18,0,0,BOWLROWS-ROW(AR17)-ROW(Table9[[#Headers],[BOWLER CUML WICKETS]])),0)>0,0,SUMIF($AR$6:AR17,Table9[[#This Row],[Bowler]],$AU$6:AU17)),SUMIF($AR$6:AR17,Table9[[#This Row],[Bowler]],$AU$6:AU17)) -> 0 | BL17: =Table9[[#This Row],[BOWLER CUML WICKETS]]*100-Table9[[#This Row],[BOWLER CUML RUNS]] -> 0
